Workbook

Sheet raw
A1: Table F33: Wood and biomass waste price and expenditure estimates, 2023 | M1: link
A2: State | B2: Prices | G2: Expenditures | M2: https://www.eia.gov/state/seds/data.php?incfile=/state/seds/sep_fuel/html/fuel_pr_ww.html&sid=US
B3: Wood | C3: Wood and biomass waste a | F3: Total b | G3: Wood | H3: Wood and biomass waste a | K3: Total b
B4: Residential | C4: Commercial | D4: Industrial | E4: Electric power | G4: Residential | H4: Commercial | I4: Industrial | J4: Electric power
B5: Dollars per million Btu | G5: Million dollars
A6: Alabama | B6: 11.95 | C6: 11.95 | D6: 3.32 | E6: 2.93 | F6: 3.44 | G6: 18.4 | H6: 3.3 | I6: 431.2 | J6: 1.3 | K6: 454.2
A7: Alaska | B7: 16.07 | C7: 5.7 | D7: 1.52 | E7: — | F7: 11.53 | G7: 16.3 | H7: 3.3 | I7: 0.2 | J7: — | K7: 19.8
A8: Arizona | B8: 16.07 | C8: 16.07 | D8: 3.01 | E8: 2.93 | F8: 7.29 | G8: 27 | H8: 4.9 | I8: 1.4 | J8: 10.3 | K8: 43.6
A9: Arkansas | B9: 11.95 | C9: 11.84 | D9: 3.26 | E9: 2.93 | F9: 3.93 | G9: 30.2 | H9: 5.4 | I9: 114.8 | J9: 0.9 | K9: 151.4
A10: California | B10: 16.07 | C10: 3.23 | D10: 3.15 | E10: 2.93 | F10: 4.2 | G10: 137.1 | H10: 33.6 | I10: 68.2 | J10: 158 | K10: 396.9
A11: Colorado | B11: 16.07 | C11: 16.07 | D11: 3.05 | E11: 2.93 | F11: 10.09 | G11: 38.1 | H11: 6.9 | I11: 1 | J11: 5.9 | K11: 51.9
A12: Connecticut | B12: 9.58 | C12: 9.58 | D12: 2.73 | E12: 2.93 | F12: 5.44 | G12: 49.8 | H12: 9 | I12: 1.6 | J12: 27.7 | K12: 88.1
A13: Delaware | B13: 11.95 | C13: 11.95 | D13: 1.17 | E13: 2.93 | F13: 4.99 | G13: 3.2 | H13: 0.6 | I13: 0.3 | J13: 1.7 | K13: 5.8
A14: Dist. of Col. | B14: — | C14: 1.01 | E14: — | F14: 1.01 | G14: — | H14: 1 | I14: — | J14: — | K14: 1
A15: Florida | B15: 11.95 | C15: 1.03 | D15: 2.57 | E15: 2.62 | F15: 2.44 | G15: 1.1 | H15: 9.5 | I15: 139.1 | J15: 80 | K15: 229.6
A16: Georgia | B16: 11.95 | C16: 11.95 | D16: 3.3 | E16: 2.93 | F16: 3.36 | G16: 23.3 | H16: 4.2 | I16: 501.7 | J16: 78.6 | K16: 607.7
A17: Hawaii | B17: 16.07 | C17: 1.02 | D17: 2.98 | E17: 2.93 | F17: 1.74 | G17: 0.1 | H17: 2.9 | I17: 0.1 | J17: 4.8 | K17: 8
A18: Idaho | B18: 16.07 | C18: 9.34 | D18: 3.31 | E18: 2.93 | F18: 4.92 | G18: 38 | H18: 7.2 | I18: 55.4 | J18: 4 | K18: 104.6
A19: Illinois | B19: 12.07 | C19: 12.07 | D19: 2.32 | E19: 0.71 | F19: 5.12 | G19: 36.2 | H19: 6.5 | I19: 6.1 | J19: 2.8 | K19: 51.5
A20: Indiana | B20: 12.07 | C20: 2.27 | D20: 2.61 | E20: 0.6 | F20: 3.73 | G20: 29.5 | H20: 8.7 | I20: 15.9 | J20: 1.5 | K20: 55.6
A21: Iowa | B21: 12.07 | C21: 5.56 | D21: 2.65 | E21: 2.93 | F21: 4.42 | G21: 18.3 | H21: 4.9 | I21: 15.3 | J21: 4.5 | K21: 42.9
A22: Kansas | B22: 12.07 | C22: 12.07 | D22: 1.21 | E22: 2.93 | F22: 5.64 | G22: 10 | H22: 1.8 | I22: 1.1 | J22: 2.2 | K22: 15.1
A23: Kentucky | B23: 11.95 | C23: 11.95 | D23: 3.05 | E23: 0.86 | F23: 3.84 | G23: 21.5 | H23: 3.9 | I23: 53.4 | J23: 1 | K23: 79.7
A24: Louisiana | B24: 11.95 | C24: 11.95 | D24: 3.15 | E24: 2.93 | F24: 3.16 | G24: 1.9 | H24: 0.3 | I24: 269.2 | J24: 4.1 | K24: 275.5
A25: Maine | B25: 9.58 | C25: 7.29 | D25: 3.28 | E25: 2.93 | F25: 4.03 | G25: 53.4 | H25: 10 | I25: 75.3 | J25: 47.8 | K25: 186.4
A26: Maryland | B26: 11.95 | C26: 8.75 | D26: 2.65 | E26: 2.93 | F26: 5.49 | G26: 26.2 | H26: 5.5 | I26: 1.1 | J26: 17.2 | K26: 50
... A30: Mississippi | B30: 11.95 | C30: 11.95 | D30: 3.29 | E30: 2.93 | F30: 3.37 | G30: 4.3 | H30: 0.8 | I30: 139.9 | J30: 0.2 | K30: 145.3
A31: Missouri | B31: 12.07 | C31: 6.11 | D31: 2.72 | E31: — | F31: 7.73 | G31: 32.3 | H31: 9.2 | I31: 2 | J31: — | K31: 43.5
A32: Montana | B32: 16.07 | C32: 16.07 | D32: 2.8 | E32: 2.93 | F32: 12.07 | G32: 34.2 | H32: 6.1 | I32: 2.8 | J32: 0.2 | K32: 43.4
A33: Nebraska | B33: 12.07 | C33: 4.56 | D33: 1.33 | E33: 2.93 | F33: 4.79 | G33: 7.3 | H33: 1.5 | I33: 1 | J33: 2.6 | K33: 12.4
A34: Nevada | B34: 16.07 | C34: 16.07 | D34: 3.01 | E34: 2.93 | F34: 10.22 | G34: 14.1 | H34: 2.5 | I34: 0.3 | J34: 2.1 | K34: 19.1
A35: New Hampshire | B35: 9.58 | C35: 6.58 | D35: 1.68 | E35: 2.93 | F35: 4.96 | G35: 50 | H35: 9.5 | I35: 2 | J35: 32.4 | K35: 93.9
A36: New Jersey | B36: 9.58 | C36: 1.88 | D36: 2.2 | E36: 2.93 | F36: 4.1 | G36: 41 | H36: 14.2 | I36: 0.9 | J36: 14.7 | K36: 70.8
A37: New Mexico | B37: 16.07 | C37: 16.07 | D37: 3.45 | E37: 2.93 | F37: 15.41 | G37: 37.5 | H37: 6.7 | I37: (s) | J37: 0.4 | K37: 44.7
A38: New York | B38: 9.58 | C38: 2.26 | D38: 2.75 | E38: 2.93 | F38: 4.37 | G38: 129.5 | H38: 37.7 | I38: 30.5 | J38: 34.9 | K38: 232.6
A39: North Carolina | B39: 11.95 | C39: 11.95 | D39: 3.29 | E39: 2.93 | F39: 3.65 | G39: 32.4 | H39: 5.8 | I39: 177.4 | J39: 28.6 | K39: 244.2
A40: North Dakota | B40: 12.07 | C40: 12.07 | D40: 2.53 | E40: — | F40: 8.03 | G40: 1.4 | H40: 0.3 | I40: 0.3 | J40: — | K40: 1.9
A41: Ohio | B41: 12.07 | C41: 11.51 | D41: 2.31 | E41: 2.93 | F41: 5.83 | G41: 93.9 | H41: 16.9 | I41: 33.2 | J41: 6.2 | K41: 150.3
A42: Oklahoma | B42: 11.95 | C42: 4.18 | D42: 2.64 | E42: 2.93 | F42: 3.88 | G42: 29 | H42: 6.3 | I42: 42.2 | J42: 0.5 | K42: 78
A43: Oregon | B43: 16.07 | C43: 11.84 | D43: 3.18 | E43: 2.93 | F43: 5.2 | G43: 84.5 | H43: 15.6 | I43: 84 | J43: 16 | K43: 200
...

Sheet logistics
A1: Term | B1: What it covers | C1: 2022 SOT $/dry ton | D1: $/kg | E1: current year $/kg | F1: note | H1: ref overall | I1: Feedstock Supply Chain Analysis
A2: Grower payment | B2: Stumpage/gate price paid to landowner/wood source (your state price usually goes here). | C2: 9.74 | D2: 0.01074 | E2: =IFERROR((D2*VLOOKUP($I$2,INDICES!$I$13:$J$58,2,0)/VLOOKUP($I$3,INDICES!$I$13:$J$58,2,0)),0) -> 0.011301768 | H2: current year | I2: 2025
A3: Harvest & collection | B3: Felling/skidding or residue gathering to landing. | C3: 4.94 | D3: 0.00545 | E3: =IFERROR((D3*VLOOKUP($I$2,INDICES!$I$13:$J$58,2,0)/VLOOKUP($I$3,INDICES!$I$13:$J$58,2,0)),0) -> 0.0057350685 | H3: reference year | I3: 2022
A4: Field-side preprocessing | B4: In-forest bundling/chipping/primary sizing at landing. | C4: 8.41 | D4: 0.00927 | E4: =IFERROR((D4*VLOOKUP($I$2,INDICES!$I$13:$J$58,2,0)/VLOOKUP($I$3,INDICES!$I$13:$J$58,2,0)),0) -> 0.009754878
A5: Transportation | B5: Truck haul from landing to depot/biorefinery (modeled draw radius). | C5: 10.84 | D5: 0.01195 | E5: =IFERROR((D5*VLOOKUP($I$2,INDICES!$I$13:$J$58,2,0)/VLOOKUP($I$3,INDICES!$I$13:$J$58,2,0)),0) -> 0.012575058
A6: Storage | B6: Pile/yard storage, losses & ops. | C6: 0.68 | D6: 0.00075 | E6: =IFERROR((D6*VLOOKUP($I$2,INDICES!$I$13:$J$58,2,0)/VLOOKUP($I$3,INDICES!$I$13:$J$58,2,0)),0) -> 0.00078922961
A7: Preprocessing | B7: Depot/biorefinery size-reduction, drying, fractionation to reactor spec (you said you’ll supply this). | C7: 29 | D7: 0.03197 | E7: =IFERROR((D7*VLOOKUP($I$2,INDICES!$I$13:$J$58,2,0)/VLOOKUP($I$3,INDICES!$I$13:$J$58,2,0)),0) -> 0.033642227 | F7: this process feedstock to 10% moisture, we include in A100
A8: Handling | B8: Queuing and plant-gate handling to reactor throat (you’ll supply this). | C8: 2.65 | D8: 0.00292 | E8: =IFERROR((D8*VLOOKUP($I$2,INDICES!$I$13:$J$58,2,0)/VLOOKUP($I$3,INDICES!$I$13:$J$58,2,0)),0) -> 0.0030727339 | F8: we include in A100
A9: Preproc construction | B9: Capital charge for the preprocessing area. | C9: 2.96 | D9: 0.00326 | E9: =IFERROR((D9*VLOOKUP($I$2,INDICES!$I$13:$J$58,2,0)/VLOOKUP($I$3,INDICES!$I$13:$J$58,2,0)),0) -> 0.003430518 | F9: we include in A100
A11: exc. Preprcess to preproc construction | E11: =SUM(E2:E6) -> 0.040156002
A15: Across the U.S. after adding logistics and industrial
A16: min | B16: =MIN('2025_feed_price'!C2:C52) -> 0.063474623
A17: max | B17: =MAX('2025_feed_price'!C2:C52) -> 0.10891604

Sheet industrial
A1: Table F33: Wood and biomass waste price and expenditure estimates, 2023 | B1: 2023 | L1: kg
A2: State | B2: Industrial (Dollars per million Btu) | C2: Industrial (Dollars per kJ) | D2: Industrial (Dollars per short ton biomass) | E2: Industrial (Dollars per kg biomass) | F2: Industrial (Dollars per metric ton biomass) | G2: quote year | H2: Industrial (Dollars per kg biomass) | I2: current year | J2: StateCode | K2: minimum | L2: =MIN(H3:H54) -> 0.02331862 | M2: StateCode | N2: 0.01927 MMBtu/kg
A3: Alabama | B3: 3.32 | C3: =B3/(1000000 * 1.055) -> 3.1469194e-06 | D3: =B3/(1/17.48) -> 58.0336 | E3: =B3/(1/0.01927) -> 0.0639764 | F3: =E3*1000 -> 63.9764 | G3: 2023 | H3: =IFERROR((E3*VLOOKUP(I3,INDICES!$I$13:$J$58,2,0)/VLOOKUP(G3,INDICES!$I$13:$J$58,2,0)),0) -> 0.066169076 | I3: 2025 | J3: AL | K3: maximum | L3: =MAX(H3:H54) -> 0.068760034 | N3: MMBtu to short ton ref
A4: Alaska | B4: 1.52 | C4: =B4/(1000000 * 1.055) -> 1.4407583e-06 | D4: =B4/(1/17.48) -> 26.5696 | E4: =B4/(1/0.01927) -> 0.0292904 | F4: =E4*1000 -> 29.2904 | G4: 2023 | H4: =IFERROR((E4*VLOOKUP(I4,INDICES!$I$13:$J$58,2,0)/VLOOKUP(G4,INDICES!$I$13:$J$58,2,0)),0) -> 0.030294276 | I4: 2025 | J4: AK | K4: whole us | L4: =H54 -> 0.061784378 | M4: AK | N4: $/kg biomass using an assumed HHV of 17.48 MMBtu per short ton (dry wood & residuals) → 0.01927 MMBtu/kg
A5: Arizona | B5: 3.01 | C5: =B5/(1000000 * 1.055) -> 2.8530806e-06 | D5: =B5/(1/17.48) -> 52.6148 | E5: =B5/(1/0.01927) -> 0.0580027 | F5: =E5*1000 -> 58.0027 | G5: 2023 | H5: =IFERROR((E5*VLOOKUP(I5,INDICES!$I$13:$J$58,2,0)/VLOOKUP(G5,INDICES!$I$13:$J$58,2,0)),0) -> 0.059990638 | I5: 2025 | J5: AZ | M5: AL | N5: https://www.epa.gov/system/files/documents/2022-10/Default%20Heat%20Content%20Ratios%20for%20Help%20and%20User%20Guide%20%281%29.pdf?
A6: Arkansas | B6: 3.26 | C6: =B6/(1000000 * 1.055) -> 3.0900474e-06 | D6: =B6/(1/17.48) -> 56.9848 | E6: =B6/(1/0.01927) -> 0.0628202 | F6: =E6*1000 -> 62.8202 | G6: 2023 | H6: =IFERROR((E6*VLOOKUP(I6,INDICES!$I$13:$J$58,2,0)/VLOOKUP(G6,INDICES!$I$13:$J$58,2,0)),0) -> 0.064973249 | I6: 2025 | J6: AR | L6: t | M6: AR
A7: California | B7: 3.15 | C7: =B7/(1000000 * 1.055) -> 2.985782e-06 | D7: =B7/(1/17.48) -> 55.062 | E7: =B7/(1/0.01927) -> 0.0607005 | F7: =E7*1000 -> 60.7005 | G7: 2023 | H7: =IFERROR((E7*VLOOKUP(I7,INDICES!$I$13:$J$58,2,0)/VLOOKUP(G7,INDICES!$I$13:$J$58,2,0)),0) -> 0.0627809 | I7: 2025 | J7: CA | K7: minimum | L7: =MIN(D3:D54) -> 20.4516 | M7: AZ
A8: Colorado | B8: 3.05 | C8: =B8/(1000000 * 1.055) -> 2.8909953e-06 | D8: =B8/(1/17.48) -> 53.314 | E8: =B8/(1/0.01927) -> 0.0587735 | F8: =E8*1000 -> 58.7735 | G8: 2023 | H8: =IFERROR((E8*VLOOKUP(I8,INDICES!$I$13:$J$58,2,0)/VLOOKUP(G8,INDICES!$I$13:$J$58,2,0)),0) -> 0.060787856 | I8: 2025 | J8: CO | K8: maximum | L8: =MAX(D3:D54) -> 60.306 | M8: CA
A9: Connecticut | B9: 2.73 | C9: =B9/(1000000 * 1.055) -> 2.5876777e-06 | D9: =B9/(1/17.48) -> 47.7204 | E9: =B9/(1/0.01927) -> 0.0526071 | F9: =E9*1000 -> 52.6071 | G9: 2023 | H9: =IFERROR((E9*VLOOKUP(I9,INDICES!$I$13:$J$58,2,0)/VLOOKUP(G9,INDICES!$I$13:$J$58,2,0)),0) -> 0.054410113 | I9: 2025 | J9: CT | M9: CO
A10: Delaware | B10: 1.17 | C10: =B10/(1000000 * 1.055) -> 1.1090047e-06 | D10: =B10/(1/17.48) -> 20.4516 | E10: =B10/(1/0.01927) -> 0.0225459 | F10: =E10*1000 -> 22.5459 | G10: 2023 | H10: =IFERROR((E10*VLOOKUP(I10,INDICES!$I$13:$J$58,2,0)/VLOOKUP(G10,INDICES!$I$13:$J$58,2,0)),0) -> 0.02331862 | I10: 2025 | J10: DE | M10: CT
A11: Dist. of Col. | B11: 2.65 | C11: =B11/(1000000 * 1.055) -> 2.5118483e-06 | D11: =B11/(1/17.48) -> 46.322 | E11: =B11/(1/0.01927) -> 0.0510655 | F11: =E11*1000 -> 51.0655 | G11: 2023 | H11: =IFERROR((E11*VLOOKUP(I11,INDICES!$I$13:$J$58,2,0)/VLOOKUP(G11,INDICES!$I$13:$J$58,2,0)),0) -> 0.052815678 | I11: 2025 | J11: DC | M11: DE
A12: Florida | B12: 2.57 | C12: =B12/(1000000 * 1.055) -> 2.436019e-06 | D12: =B12/(1/17.48) -> 44.9236 | E12: =B12/(1/0.01927) -> 0.0495239 | F12: =E12*1000 -> 49.5239 | G12: 2023 | H12: =IFERROR((E12*VLOOKUP(I12,INDICES!$I$13:$J$58,2,0)/VLOOKUP(G12,INDICES!$I$13:$J$58,2,0)),0) -> 0.051221242 | I12: 2025 | J12: FL | M12: FL
A13: Georgia | B13: 3.3 | C13: =B13/(1000000 * 1.055) -> 3.1279621e-06 | D13: =B13/(1/17.48) -> 57.684 | E13: =B13/(1/0.01927) -> 0.063591 | F13: =E13*1000 -> 63.591 | G13: 2023 | H13: =IFERROR((E13*VLOOKUP(I13,INDICES!$I$13:$J$58,2,0)/VLOOKUP(G13,INDICES!$I$13:$J$58,2,0)),0) -> 0.065770467 | I13: 2025 | J13: GA | M13: GA
A14: Hawaii | B14: 2.98 | C14: =B14/(1000000 * 1.055) -> 2.8246445e-06 | D14: =B14/(1/17.48) -> 52.0904 | E14: =B14/(1/0.01927) -> 0.0574246 | F14: =E14*1000 -> 57.4246 | G14: 2023 | H14: =IFERROR((E14*VLOOKUP(I14,INDICES!$I$13:$J$58,2,0)/VLOOKUP(G14,INDICES!$I$13:$J$58,2,0)),0) -> 0.059392725 | I14: 2025 | J14: HI | M14: HI
A15: Idaho | B15: 3.31 | C15: =B15/(1000000 * 1.055) -> 3.1374408e-06 | D15: =B15/(1/17.48) -> 57.8588 | E15: =B15/(1/0.01927) -> 0.0637837 | F15: =E15*1000 -> 63.7837 | G15: 2023 | H15: =IFERROR((E15*VLOOKUP(I15,INDICES!$I$13:$J$58,2,0)/VLOOKUP(G15,INDICES!$I$13:$J$58,2,0)),0) -> 0.065969771 | I15: 2025 | J15: ID | M15: IA
A16: Illinois | B16: 2.32 | C16: =B16/(1000000 * 1.055) -> 2.1990521e-06 | D16: =B16/(1/17.48) -> 40.5536 | E16: =B16/(1/0.01927) -> 0.0447064 | F16: =E16*1000 -> 44.7064 | G16: 2023 | H16: =IFERROR((E16*VLOOKUP(I16,INDICES!$I$13:$J$58,2,0)/VLOOKUP(G16,INDICES!$I$13:$J$58,2,0)),0) -> 0.046238631 | I16: 2025 | J16: IL | M16: ID
A17: Indiana | B17: 2.61 | C17: =B17/(1000000 * 1.055) -> 2.4739336e-06 | D17: =B17/(1/17.48) -> 45.6228 | E17: =B17/(1/0.01927) -> 0.0502947 | F17: =E17*1000 -> 50.2947 | G17: 2023 | H17: =IFERROR((E17*VLOOKUP(I17,INDICES!$I$13:$J$58,2,0)/VLOOKUP(G17,INDICES!$I$13:$J$58,2,0)),0) -> 0.05201846 | I17: 2025 | J17: IN | M17: IL
A18: Iowa | B18: 2.65 | C18: =B18/(1000000 * 1.055) -> 2.5118483e-06 | D18: =B18/(1/17.48) -> 46.322 | E18: =B18/(1/0.01927) -> 0.0510655 | F18: =E18*1000 -> 51.0655 | G18: 2023 | H18: =IFERROR((E18*VLOOKUP(I18,INDICES!$I$13:$J$58,2,0)/VLOOKUP(G18,INDICES!$I$13:$J$58,2,0)),0) -> 0.052815678 | I18: 2025 | J18: IA | M18: IN
A19: Kansas | B19: 1.21 | C19: =B19/(1000000 * 1.055) -> 1.1469194e-06 | D19: =B19/(1/17.48) -> 21.1508 | E19: =B19/(1/0.01927) -> 0.0233167 | F19: =E19*1000 -> 23.3167 | G19: 2023 | H19: =IFERROR((E19*VLOOKUP(I19,INDICES!$I$13:$J$58,2,0)/VLOOKUP(G19,INDICES!$I$13:$J$58,2,0)),0) -> 0.024115838 | I19: 2025 | J19: KS | M19: KS
A20: Kentucky | B20: 3.05 | C20: =B20/(1000000 * 1.055) -> 2.8909953e-06 | D20: =B20/(1/17.48) -> 53.314 | E20: =B20/(1/0.01927) -> 0.0587735 | F20: =E20*1000 -> 58.7735 | G20: 2023 | H20: =IFERROR((E20*VLOOKUP(I20,INDICES!$I$13:$J$58,2,0)/VLOOKUP(G20,INDICES!$I$13:$J$58,2,0)),0) -> 0.060787856 | I20: 2025 | J20: KY | M20: KY
... A53: Wyoming | B53: 2.94 | C53: =B53/(1000000 * 1.055) -> 2.7867299e-06 | D53: =B53/(1/17.48) -> 51.3912 | E53: =B53/(1/0.01927) -> 0.0566538 | F53: =E53*1000 -> 56.6538 | G53: 2023 | H53: =IFERROR((E53*VLOOKUP(I53,INDICES!$I$13:$J$58,2,0)/VLOOKUP(G53,INDICES!$I$13:$J$58,2,0)),0) -> 0.058595507 | I53: 2025 | J53: WY | M53: WY
A54: United States | B54: 3.1 | C54: =B54/(1000000 * 1.055) -> 2.9383886e-06 | D54: =B54/(1/17.48) -> 54.188 | E54: =B54/(1/0.01927) -> 0.059737 | F54: =E54*1000 -> 59.737 | G54: 2023 | H54: =IFERROR((E54*VLOOKUP(I54,INDICES!$I$13:$J$58,2,0)/VLOOKUP(G54,INDICES!$I$13:$J$58,2,0)),0) -> 0.061784378 | I54: 2025

Sheet 2025_feed_price
A1: State | B1: industrial_dollar_per_kg | C1: industrial_logistics_per_kg | D1: StateCode
A2: Alabama | B2: 0.066169076 | C2: =B2+logistics!$E$11 -> 0.10632508 | D2: AL
A3: Alaska | B3: 0.030294276 | C3: =B3+logistics!$E$11 -> 0.070450278 | D3: AK
A4: Arizona | B4: 0.059990638 | C4: =B4+logistics!$E$11 -> 0.10014664 | D4: AZ
A5: Arkansas | B5: 0.064973249 | C5: =B5+logistics!$E$11 -> 0.10512925 | D5: AR
A6: California | B6: 0.0627809 | C6: =B6+logistics!$E$11 -> 0.1029369 | D6: CA
A7: Colorado | B7: 0.060787856 | C7: =B7+logistics!$E$11 -> 0.10094386 | D7: CO
A8: Connecticut | B8: 0.054410113 | C8: =B8+logistics!$E$11 -> 0.094566116 | D8: CT
A9: Delaware | B9: 0.02331862 | C9: =B9+logistics!$E$11 -> 0.063474623 | D9: DE
A10: Dist. of Col. | B10: 0.052815678 | C10: =B10+logistics!$E$11 -> 0.09297168 | D10: DC
A11: Florida | B11: 0.051221242 | C11: =B11+logistics!$E$11 -> 0.091377245 | D11: FL
A12: Georgia | B12: 0.065770467 | C12: =B12+logistics!$E$11 -> 0.10592647 | D12: GA
A13: Hawaii | B13: 0.059392725 | C13: =B13+logistics!$E$11 -> 0.099548727 | D13: HI
... A52: Wyoming | B52: 0.058595507 | C52: =B52+logistics!$E$11 -> 0.098751509 | D52: WY

Sheet commercial
A1: State | B1: Prices
B2: Wood | C2: Wood and biomass waste a | F2: Total b
B3: Residential | C3: Commercial | D3: Industrial | E3: Electric power | G3: Commercial (Dollars per short ton biomass) | H3: Commercial (Dollars per kg biomass) | I3: Commercial (Dollars per metric ton biomass)
B4: Dollars per million Btu
A5: Alabama | B5: 11.95 | C5: 11.95 | D5: 3.32 | E5: 2.93 | F5: 3.44 | G5: =C5/(1/17.48) -> 208.886 | H5: =G5/1000 -> 0.208886
A6: Alaska | B6: 16.07 | C6: 5.7 | D6: 1.52 | E6: — | F6: 11.53 | G6: =C6/(1/17.48) -> 99.636 | H6: =G6/1000 -> 0.099636
A7: Arizona | B7: 16.07 | C7: 16.07 | D7: 3.01 | E7: 2.93 | F7: 7.29 | G7: =C7/(1/17.48) -> 280.9036 | H7: =G7/1000 -> 0.2809036
A8: Arkansas | B8: 11.95 | C8: 11.84 | D8: 3.26 | E8: 2.93 | F8: 3.93 | G8: =C8/(1/17.48) -> 206.9632 | H8: =G8/1000 -> 0.2069632
A9: California | B9: 16.07 | C9: 3.23 | D9: 3.15 | E9: 2.93 | F9: 4.2 | G9: =C9/(1/17.48) -> 56.4604 | H9: =G9/1000 -> 0.0564604
A10: Colorado | B10: 16.07 | C10: 16.07 | D10: 3.05 | E10: 2.93 | F10: 10.09 | G10: =C10/(1/17.48) -> 280.9036 | H10: =G10/1000 -> 0.2809036
A11: Connecticut | B11: 9.58 | C11: 9.58 | D11: 2.73 | E11: 2.93 | F11: 5.44 | G11: =C11/(1/17.48) -> 167.4584 | H11: =G11/1000 -> 0.1674584
A12: Delaware | B12: 11.95 | C12: 11.95 | D12: 1.17 | E12: 2.93 | F12: 4.99 | G12: =C12/(1/17.48) -> 208.886 | H12: =G12/1000 -> 0.208886
A13: Dist. of Col. | B13: — | C13: 1.01 | E13: — | F13: 1.01 | G13: =C13/(1/17.48) -> 17.6548 | H13: =G13/1000 -> 0.0176548
A14: Florida | B14: 11.95 | C14: 1.03 | D14: 2.57 | E14: 2.62 | F14: 2.44 | G14: =C14/(1/17.48) -> 18.0044 | H14: =G14/1000 -> 0.0180044
A15: Georgia | B15: 11.95 | C15: 11.95 | D15: 3.3 | E15: 2.93 | F15: 3.36 | G15: =C15/(1/17.48) -> 208.886 | H15: =G15/1000 -> 0.208886
A16: Hawaii | B16: 16.07 | C16: 1.02 | D16: 2.98 | E16: 2.93 | F16: 1.74 | G16: =C16/(1/17.48) -> 17.8296 | H16: =G16/1000 -> 0.0178296
A17: Idaho | B17: 16.07 | C17: 9.34 | D17: 3.31 | E17: 2.93 | F17: 4.92 | G17: =C17/(1/17.48) -> 163.2632 | H17: =G17/1000 -> 0.1632632
A18: Illinois | B18: 12.07 | C18: 12.07 | D18: 2.32 | E18: 0.71 | F18: 5.12 | G18: =C18/(1/17.48) -> 210.9836 | H18: =G18/1000 -> 0.2109836
A19: Indiana | B19: 12.07 | C19: 2.27 | D19: 2.61 | E19: 0.6 | F19: 3.73 | G19: =C19/(1/17.48) -> 39.6796 | H19: =G19/1000 -> 0.0396796
A20: Iowa | B20: 12.07 | C20: 5.56 | D20: 2.65 | E20: 2.93 | F20: 4.42 | G20: =C20/(1/17.48) -> 97.1888 | H20: =G20/1000 -> 0.0971888
A21: Kansas | B21: 12.07 | C21: 12.07 | D21: 1.21 | E21: 2.93 | F21: 5.64 | G21: =C21/(1/17.48) -> 210.9836 | H21: =G21/1000 -> 0.2109836
A22: Kentucky | B22: 11.95 | C22: 11.95 | D22: 3.05 | E22: 0.86 | F22: 3.84 | G22: =C22/(1/17.48) -> 208.886 | H22: =G22/1000 -> 0.208886
A23: Louisiana | B23: 11.95 | C23: 11.95 | D23: 3.15 | E23: 2.93 | F23: 3.16 | G23: =C23/(1/17.48) -> 208.886 | H23: =G23/1000 -> 0.208886
A24: Maine | B24: 9.58 | C24: 7.29 | D24: 3.28 | E24: 2.93 | F24: 4.03 | G24: =C24/(1/17.48) -> 127.4292 | H24: =G24/1000 -> 0.1274292
A25: Maryland | B25: 11.95 | C25: 8.75 | D25: 2.65 | E25: 2.93 | F25: 5.49 | G25: =C25/(1/17.48) -> 152.95 | H25: =G25/1000 -> 0.15295
... A29: Mississippi | B29: 11.95 | C29: 11.95 | D29: 3.29 | E29: 2.93 | F29: 3.37 | G29: =C29/(1/17.48) -> 208.886 | H29: =G29/1000 -> 0.208886
A30: Missouri | B30: 12.07 | C30: 6.11 | D30: 2.72 | E30: — | F30: 7.73 | G30: =C30/(1/17.48) -> 106.8028 | H30: =G30/1000 -> 0.1068028
A31: Montana | B31: 16.07 | C31: 16.07 | D31: 2.8 | E31: 2.93 | F31: 12.07 | G31: =C31/(1/17.48) -> 280.9036 | H31: =G31/1000 -> 0.2809036
A32: Nebraska | B32: 12.07 | C32: 4.56 | D32: 1.33 | E32: 2.93 | F32: 4.79 | G32: =C32/(1/17.48) -> 79.7088 | H32: =G32/1000 -> 0.0797088
A33: Nevada | B33: 16.07 | C33: 16.07 | D33: 3.01 | E33: 2.93 | F33: 10.22 | G33: =C33/(1/17.48) -> 280.9036 | H33: =G33/1000 -> 0.2809036
A34: New Hampshire | B34: 9.58 | C34: 6.58 | D34: 1.68 | E34: 2.93 | F34: 4.96 | G34: =C34/(1/17.48) -> 115.0184 | H34: =G34/1000 -> 0.1150184
A35: New Jersey | B35: 9.58 | C35: 1.88 | D35: 2.2 | E35: 2.93 | F35: 4.1 | G35: =C35/(1/17.48) -> 32.8624 | H35: =G35/1000 -> 0.0328624
A36: New Mexico | B36: 16.07 | C36: 16.07 | D36: 3.45 | E36: 2.93 | F36: 15.41 | G36: =C36/(1/17.48) -> 280.9036 | H36: =G36/1000 -> 0.2809036
A37: New York | B37: 9.58 | C37: 2.26 | D37: 2.75 | E37: 2.93 | F37: 4.37 | G37: =C37/(1/17.48) -> 39.5048 | H37: =G37/1000 -> 0.0395048
A38: North Carolina | B38: 11.95 | C38: 11.95 | D38: 3.29 | E38: 2.93 | F38: 3.65 | G38: =C38/(1/17.48) -> 208.886 | H38: =G38/1000 -> 0.208886
A39: North Dakota | B39: 12.07 | C39: 12.07 | D39: 2.53 | E39: — | F39: 8.03 | G39: =C39/(1/17.48) -> 210.9836 | H39: =G39/1000 -> 0.2109836
A40: Ohio | B40: 12.07 | C40: 11.51 | D40: 2.31 | E40: 2.93 | F40: 5.83 | G40: =C40/(1/17.48) -> 201.1948 | H40: =G40/1000 -> 0.2011948
A41: Oklahoma | B41: 11.95 | C41: 4.18 | D41: 2.64 | E41: 2.93 | F41: 3.88 | G41: =C41/(1/17.48) -> 73.0664 | H41: =G41/1000 -> 0.0730664
A42: Oregon | B42: 16.07 | C42: 11.84 | D42: 3.18 | E42: 2.93 | F42: 5.2 | G42: =C42/(1/17.48) -> 206.9632 | H42: =G42/1000 -> 0.2069632
A43: Pennsylvania | B43: 9.58 | C43: 4.89 | D43: 2.24 | E43: 2.93 | F43: 4.51 | G43: =C43/(1/17.48) -> 85.4772 | H43: =G43/1000 -> 0.0854772
...

Sheet INDICES
B2: Plant Cost Indices | I2: PPI Chemical Index | Q2: Labor Index
B3: Source: | C3: (1)Chemical Engineering Magazine | I3: Source: | J3: https://fred.stlouisfed.org/series/PCU325325#0 | Q3: Source: | R3: (1) Bureau of Labor Statistics
Q4: Series ID: | R4: CEU3232500008
Q5: Chemicals
Q6: Average Hourly Earnings of Production Workers
R7: Current indices @
A12: Source | B12: Year | C12: Index | I12: Year | J12: Price Index | Q12: Year | R12: Price Index
A13: (1) | B13: 1990 | C13: 357.6 | H13: (1) | I13: 1980 | J13: 89 | P13: Calculated | Q13: 1980 | R13: 9.0457143
A14: (1) | B14: 1991 | C14: 361.3 | H14: (1) | I14: 1981 | J14: 98.4 | P14: Calculated | Q14: 1981 | R14: 9.4288571
A15: (1) | B15: 1992 | C15: 358.2 | H15: (1) | I15: 1982 | J15: 100 | P15: Calculated | Q15: 1982 | R15: 9.812
A16: (1) | B16: 1993 | C16: 359.2 | H16: (1) | I16: 1983 | J16: 100.3 | P16: Calculated | Q16: 1983 | R16: 10.195143
A17: (1) | B17: 1994 | C17: 368.1 | H17: (1) | I17: 1984 | J17: 102.9 | P17: Calculated | Q17: 1984 | R17: 10.578286
A18: (1) | B18: 1995 | C18: 381.1 | H18: (1) | I18: 1985 | J18: 103.7 | P18: Calculated | Q18: 1985 | R18: 10.961429
A19: (1) | B19: 1996 | C19: 381.7 | H19: (1) | I19: 1986 | J19: 102.6 | P19: Calculated | Q19: 1986 | R19: 11.344571
A20: (1) | B20: 1997 | C20: 386.5 | H20: (1) | I20: 1987 | J20: 106.4 | P20: Calculated | Q20: 1987 | R20: 11.727714
A21: (1) | B21: 1998 | C21: 389.5 | H21: (1) | I21: 1988 | J21: 116.3 | P21: Calculated | Q21: 1988 | R21: 12.110857
A22: (1) | B22: 1999 | C22: 390.6 | H22: (1) | I22: 1989 | J22: 123 | P22: Calculated | Q22: 1989 | R22: 12.494
A23: (1) | B23: 2000 | C23: 394.1 | H23: (1) | I23: 1990 | J23: 123.6 | P23: (1) | Q23: 1990 | R23: 12.85
A24: (1) | B24: 2001 | C24: 394.3 | H24: (1) | I24: 1991 | J24: 125.6 | P24: (1) | Q24: 1991 | R24: 13.3
... A48: Calculated | B48: 2025 | C48: 581.08833 | H48: (1) | I48: 2015 | J48: 264.8 | P48: (1) | Q48: 2015 | R48: 21.76
H49: (1) | I49: 2016 | J49: 267.1 | P49: (1) | Q49: 2016 | R49: 22.71
H50: (1) | I50: 2017 | J50: 277.6 | P50: (1) | Q50: 2017 | R50: 24.29
H51: (1) | I51: 2018 | J51: 290.2 | P51: (1) | Q51: 2018 | R51: 25.46
H52: (1) | I52: 2019 | J52: 292.1 | P52: (1) | Q52: 2019 | R52: 25.46
H53: (1) | I53: 2020 | J53: 288.92 | P53: Calculated | Q53: 2020 | R53: 26.835
H54: (1) | I54: 2021 | J54: 322.832 | P54: Calculated | Q54: 2021 | R54: 27.777
H55: Calculated | I55: 2022 | J55: 307.28182 | P55: Calculated | Q55: 2022 | R55: 28.719
H56: Calculated | I56: 2023 | J56: 312.63939 | P56: Calculated | Q56: 2023 | R56: 29.661
H57: Calculated | I57: 2024 | J57: 317.99697 | P57: Calculated | Q57: 2024 | R57: 30.603
H58: Calculated | I58: 2025 | J58: 323.35455 | P58: Calculated | Q58: 2025 | R58: 31.545
